2024-08-13 16:02:27,017 [Worker 0] Is distributed: False
2024-08-13 16:02:27,018 [Process: 0] Starting training
2024-08-13 16:02:27,018 [Process: 0] EPOCH 1:
2024-08-13 16:02:27,019 [Worker 0] Loss fn: soft_dice - SoftDiceLoss(), Rank 0 - True
[Worker 0] Is distributed: False
[Process: 0] Starting training
[Process: 0] EPOCH 1:
[Worker 0] Loss fn: soft_dice - SoftDiceLoss(), Rank 0 - True
Error executing job with overrides: []
Traceback (most recent call last):
  File "/home/stud/zhoy/MasterThesis_zhoy/GeoL_net/run.py", line 31, in main
    trainer.train()
  File "/home/stud/zhoy/MasterThesis_zhoy/GeoL_net/trainer/trainer.py", line 340, in train
    avg_loss, avg_metrics = self.train_one_epoch(epoch)
  File "/home/stud/zhoy/MasterThesis_zhoy/GeoL_net/trainer/trainer.py", line 179, in train_one_epoch
    for i, batch in enumerate(self.train_loader):
  File "/home/stud/zhoy/anaconda3/envs/o2o/lib/python3.8/site-packages/torch/utils/data/dataloader.py", line 634, in __next__
    data = self._next_data()
  File "/home/stud/zhoy/anaconda3/envs/o2o/lib/python3.8/site-packages/torch/utils/data/dataloader.py", line 1346, in _next_data
    return self._process_data(data)
  File "/home/stud/zhoy/anaconda3/envs/o2o/lib/python3.8/site-packages/torch/utils/data/dataloader.py", line 1372, in _process_data
    data.reraise()
  File "/home/stud/zhoy/anaconda3/envs/o2o/lib/python3.8/site-packages/torch/_utils.py", line 644, in reraise
    raise exception
IndexError: Caught IndexError in DataLoader worker process 0.
Original Traceback (most recent call last):
  File "/home/stud/zhoy/anaconda3/envs/o2o/lib/python3.8/site-packages/torch/utils/data/_utils/worker.py", line 308, in _worker_loop
    data = fetcher.fetch(index)
  File "/home/stud/zhoy/anaconda3/envs/o2o/lib/python3.8/site-packages/torch/utils/data/_utils/fetch.py", line 51, in fetch
    data = [self.dataset[idx] for idx in possibly_batched_index]
  File "/home/stud/zhoy/anaconda3/envs/o2o/lib/python3.8/site-packages/torch/utils/data/_utils/fetch.py", line 51, in <listcomp>
    data = [self.dataset[idx] for idx in possibly_batched_index]
  File "/home/stud/zhoy/MasterThesis_zhoy/GeoL_net/dataset/dataset.py", line 128, in __getitem__
    fps_points_scene_from_original = scene_pcd_points[fps_indices_scene_np]
IndexError: index 0 is out of bounds for axis 0 with size 0
Set the environment variable HYDRA_FULL_ERROR=1 for a complete stack trace.