[Worker 0] Is distributed: False
[Process: 0] Starting training
[Process: 0] EPOCH 1:
[Worker 0] Loss fn: soft_dice - SoftDiceLoss(), Rank 0 - True
2024-08-13 15:58:07,715 [Worker 0] Is distributed: False
2024-08-13 15:58:07,716 [Process: 0] Starting training
2024-08-13 15:58:07,716 [Process: 0] EPOCH 1:
2024-08-13 15:58:07,718 [Worker 0] Loss fn: soft_dice - SoftDiceLoss(), Rank 0 - True
Error executing job with overrides: []
Traceback (most recent call last):
  File "/home/stud/zhoy/MasterThesis_zhoy/GeoL_net/run.py", line 31, in main
    trainer.train()
  File "/home/stud/zhoy/MasterThesis_zhoy/GeoL_net/trainer/trainer.py", line 340, in train
    avg_loss, avg_metrics = self.train_one_epoch(epoch)
  File "/home/stud/zhoy/MasterThesis_zhoy/GeoL_net/trainer/trainer.py", line 179, in train_one_epoch
    for i, batch in enumerate(self.train_loader):
  File "/home/stud/zhoy/anaconda3/envs/o2o/lib/python3.8/site-packages/torch/utils/data/dataloader.py", line 634, in __next__
    data = self._next_data()
  File "/home/stud/zhoy/anaconda3/envs/o2o/lib/python3.8/site-packages/torch/utils/data/dataloader.py", line 1346, in _next_data
    return self._process_data(data)
  File "/home/stud/zhoy/anaconda3/envs/o2o/lib/python3.8/site-packages/torch/utils/data/dataloader.py", line 1372, in _process_data
    data.reraise()
  File "/home/stud/zhoy/anaconda3/envs/o2o/lib/python3.8/site-packages/torch/_utils.py", line 644, in reraise
    raise exception
RuntimeError: Caught RuntimeError in DataLoader worker process 0.
Original Traceback (most recent call last):
  File "/home/stud/zhoy/anaconda3/envs/o2o/lib/python3.8/site-packages/torch/utils/data/_utils/worker.py", line 308, in _worker_loop
    data = fetcher.fetch(index)
  File "/home/stud/zhoy/anaconda3/envs/o2o/lib/python3.8/site-packages/torch/utils/data/_utils/fetch.py", line 51, in fetch
    data = [self.dataset[idx] for idx in possibly_batched_index]
  File "/home/stud/zhoy/anaconda3/envs/o2o/lib/python3.8/site-packages/torch/utils/data/_utils/fetch.py", line 51, in <listcomp>
    data = [self.dataset[idx] for idx in possibly_batched_index]
  File "/home/stud/zhoy/MasterThesis_zhoy/GeoL_net/dataset/dataset.py", line 126, in __getitem__
    fps_indices_scene = pointnet2_utils.furthest_point_sample(scene_pcd_tensor, 4096)
  File "/home/stud/zhoy/anaconda3/envs/o2o/lib/python3.8/site-packages/torch/autograd/function.py", line 506, in apply
    return super().apply(*args, **kwargs)  # type: ignore[misc]
  File "/home/stud/zhoy/anaconda3/envs/o2o/lib/python3.8/site-packages/pointnet2_ops/pointnet2_utils.py", line 54, in forward
    out = _ext.furthest_point_sampling(xyz, npoint)
RuntimeError: CUDA error: out of memory
CUDA kernel errors might be asynchronously reported at some other API call, so the stacktrace below might be incorrect.
For debugging consider passing CUDA_LAUNCH_BLOCKING=1.
Compile with `TORCH_USE_CUDA_DSA` to enable device-side assertions.
Set the environment variable HYDRA_FULL_ERROR=1 for a complete stack trace.