2024-08-13 17:01:58,248 [Worker 0] Is distributed: False
2024-08-13 17:01:58,248 [Process: 0] Starting training
2024-08-13 17:01:58,249 [Process: 0] EPOCH 1:
2024-08-13 17:01:58,250 [Worker 0] Loss fn: soft_dice - SoftDiceLoss(), Rank 0 - True
Error executing job with overrides: []
Traceback (most recent call last):
  File "/home/stud/zhoy/anaconda3/envs/o2o/lib/python3.8/site-packages/hydra/_internal/utils.py", line 211, in run_and_report
    return func()
  File "/home/stud/zhoy/anaconda3/envs/o2o/lib/python3.8/site-packages/hydra/_internal/utils.py", line 368, in <lambda>
    lambda: hydra.run(
  File "/home/stud/zhoy/anaconda3/envs/o2o/lib/python3.8/site-packages/hydra/_internal/hydra.py", line 110, in run
    _ = ret.return_value
  File "/home/stud/zhoy/anaconda3/envs/o2o/lib/python3.8/site-packages/hydra/core/utils.py", line 233, in return_value
    raise self._return_value
  File "/home/stud/zhoy/anaconda3/envs/o2o/lib/python3.8/site-packages/hydra/core/utils.py", line 160, in run_job
    ret.return_value = task_function(task_cfg)
  File "/home/stud/zhoy/MasterThesis_zhoy/GeoL_net/run.py", line 31, in main
    trainer.train()
  File "/home/stud/zhoy/MasterThesis_zhoy/GeoL_net/trainer/trainer.py", line 339, in train
    avg_loss, avg_metrics = self.train_one_epoch(epoch)
  File "/home/stud/zhoy/MasterThesis_zhoy/GeoL_net/trainer/trainer.py", line 179, in train_one_epoch
    for i, batch in enumerate(self.train_loader):
  File "/home/stud/zhoy/anaconda3/envs/o2o/lib/python3.8/site-packages/torch/utils/data/dataloader.py", line 634, in __next__
    data = self._next_data()
  File "/home/stud/zhoy/anaconda3/envs/o2o/lib/python3.8/site-packages/torch/utils/data/dataloader.py", line 678, in _next_data
    data = self._dataset_fetcher.fetch(index)  # may raise StopIteration
  File "/home/stud/zhoy/anaconda3/envs/o2o/lib/python3.8/site-packages/torch/utils/data/_utils/fetch.py", line 51, in fetch
    data = [self.dataset[idx] for idx in possibly_batched_index]
  File "/home/stud/zhoy/anaconda3/envs/o2o/lib/python3.8/site-packages/torch/utils/data/_utils/fetch.py", line 51, in <listcomp>
    data = [self.dataset[idx] for idx in possibly_batched_index]
  File "/home/stud/zhoy/MasterThesis_zhoy/GeoL_net/dataset/dataset.py", line 144, in __getitem__
    depth_image = np.transpose(depth_image, (2, 0, 1))
  File "<__array_function__ internals>", line 200, in transpose
  File "/home/stud/zhoy/anaconda3/envs/o2o/lib/python3.8/site-packages/numpy/core/fromnumeric.py", line 668, in transpose
    return _wrapfunc(a, 'transpose', axes)
  File "/home/stud/zhoy/anaconda3/envs/o2o/lib/python3.8/site-packages/numpy/core/fromnumeric.py", line 57, in _wrapfunc
    return bound(*args, **kwds)
ValueError: axes don't match array
During handling of the above exception, another exception occurred:
Traceback (most recent call last):
  File "/home/stud/zhoy/MasterThesis_zhoy/GeoL_net/run.py", line 37, in <module>
    main()
  File "/home/stud/zhoy/anaconda3/envs/o2o/lib/python3.8/site-packages/hydra/main.py", line 49, in decorated_main
    _run_hydra(
  File "/home/stud/zhoy/anaconda3/envs/o2o/lib/python3.8/site-packages/hydra/_internal/utils.py", line 367, in _run_hydra
    run_and_report(
  File "/home/stud/zhoy/anaconda3/envs/o2o/lib/python3.8/site-packages/hydra/_internal/utils.py", line 251, in run_and_report
    assert mdl is not None
AssertionError
[Worker 0] Is distributed: False
[Process: 0] Starting training
[Process: 0] EPOCH 1:
[Worker 0] Loss fn: soft_dice - SoftDiceLoss(), Rank 0 - True