2024-08-12 13:06:04,577 INFO    StreamThr :463961 [internal.py:wandb_internal():86] W&B internal server running at pid: 463961, started at: 2024-08-12 13:06:04.575733
2024-08-12 13:06:04,580 DEBUG   HandlerThread:463961 [handler.py:handle_request():146] handle_request: status
2024-08-12 13:06:04,591 INFO    WriterThread:463961 [datastore.py:open_for_write():87] open: /home/stud/zhoy/MasterThesis_zhoy/wandb/run-20240812_130604-6upj29ew/run-6upj29ew.wandb
2024-08-12 13:06:04,593 DEBUG   SenderThread:463961 [sender.py:send():379] send: header
2024-08-12 13:06:04,625 DEBUG   SenderThread:463961 [sender.py:send():379] send: run
2024-08-12 13:06:04,922 ERROR   SenderThread:463961 [internal_api.py:execute():373] 404 response executing GraphQL.
2024-08-12 13:06:04,922 ERROR   SenderThread:463961 [internal_api.py:execute():374] {"errors":[{"message":"project not found","path":["upsertBucket"]}],"data":{"upsertBucket":null}}
2024-08-12 13:06:04,922 ERROR   SenderThread:463961 [sender.py:send_run():971] It appears that you do not have permission to access the requested resource. Please reach out to the project owner to grant you access. If you have the correct permissions, verify that there are no issues with your networking setup.(Error 404: Not Found)
Traceback (most recent call last):
  File "/home/stud/zhoy/anaconda3/envs/o2o/lib/python3.8/site-packages/wandb/sdk/lib/retry.py", line 131, in __call__
    result = self._call_fn(*args, **kwargs)
  File "/home/stud/zhoy/anaconda3/envs/o2o/lib/python3.8/site-packages/wandb/sdk/internal/internal_api.py", line 369, in execute
    return self.client.execute(*args, **kwargs)  # type: ignore
  File "/home/stud/zhoy/anaconda3/envs/o2o/lib/python3.8/site-packages/wandb/vendor/gql-0.2.0/wandb_gql/client.py", line 52, in execute
    result = self._get_result(document, *args, **kwargs)
  File "/home/stud/zhoy/anaconda3/envs/o2o/lib/python3.8/site-packages/wandb/vendor/gql-0.2.0/wandb_gql/client.py", line 60, in _get_result
    return self.transport.execute(document, *args, **kwargs)
  File "/home/stud/zhoy/anaconda3/envs/o2o/lib/python3.8/site-packages/wandb/sdk/lib/gql_request.py", line 59, in execute
    request.raise_for_status()
  File "/home/stud/zhoy/.local/lib/python3.8/site-packages/requests/models.py", line 1021, in raise_for_status
    raise HTTPError(http_error_msg, response=self)
requests.exceptions.HTTPError: 404 Client Error: Not Found for url: https://api.wandb.ai/graphql

During handling of the above exception, another exception occurred:

Traceback (most recent call last):
  File "/home/stud/zhoy/anaconda3/envs/o2o/lib/python3.8/site-packages/wandb/sdk/internal/sender.py", line 969, in send_run
    server_run = self._init_run(run, config_value_dict)
  File "/home/stud/zhoy/anaconda3/envs/o2o/lib/python3.8/site-packages/wandb/sdk/internal/sender.py", line 1014, in _init_run
    server_run, inserted, server_messages = self._api.upsert_run(
  File "/home/stud/zhoy/anaconda3/envs/o2o/lib/python3.8/site-packages/wandb/apis/normalize.py", line 73, in wrapper
    raise err
  File "/home/stud/zhoy/anaconda3/envs/o2o/lib/python3.8/site-packages/wandb/apis/normalize.py", line 41, in wrapper
    return func(*args, **kwargs)
  File "/home/stud/zhoy/anaconda3/envs/o2o/lib/python3.8/site-packages/wandb/sdk/internal/internal_api.py", line 2217, in upsert_run
    response = self.gql(
  File "/home/stud/zhoy/anaconda3/envs/o2o/lib/python3.8/site-packages/wandb/sdk/internal/internal_api.py", line 341, in gql
    ret = self._retry_gql(
  File "/home/stud/zhoy/anaconda3/envs/o2o/lib/python3.8/site-packages/wandb/sdk/lib/retry.py", line 147, in __call__
    retry_timedelta_triggered = check_retry_fn(e)
  File "/home/stud/zhoy/anaconda3/envs/o2o/lib/python3.8/site-packages/wandb/util.py", line 968, in check_retry_fn
    return fallback_retry_fn(e)
  File "/home/stud/zhoy/anaconda3/envs/o2o/lib/python3.8/site-packages/wandb/util.py", line 910, in no_retry_auth
    raise CommError(
wandb.errors.CommError: It appears that you do not have permission to access the requested resource. Please reach out to the project owner to grant you access. If you have the correct permissions, verify that there are no issues with your networking setup.(Error 404: Not Found)
2024-08-12 13:06:05,154 DEBUG   HandlerThread:463961 [handler.py:handle_request():146] handle_request: shutdown
2024-08-12 13:06:05,154 INFO    HandlerThread:463961 [handler.py:finish():866] shutting down handler
2024-08-12 13:06:05,625 INFO    WriterThread:463961 [datastore.py:close():296] close: /home/stud/zhoy/MasterThesis_zhoy/wandb/run-20240812_130604-6upj29ew/run-6upj29ew.wandb
2024-08-12 13:06:05,933 INFO    SenderThread:463961 [sender.py:finish():1546] shutting down sender
